Workbook

Sheet Blad1
B1: opmerking | C1: ro/adhoc | F1: NR TEGEL | G1: TEGELNAAM | H1: AccountTypeNR | J1: AccountType | K1: LEVEL 2 | M1: MaxAmt | O1: MaterialGroup | P1: DeliverTo | Q1: CommonIdDomain | R1: ItemCategory | S1: Asset | T1: WBSElement | U1: SAPPurchaseGroup | V1: CurrForMinAndMaxAmt | W1: AccountCategory | X1: InternalOrder | Y1: CompanyCode | Z1: MinAmt | AA1: CommonId | AB1: Omschrijving tegel | AC1: BTW-conditietabel | AD1: btw-tarief | AE1: L/D | AF1: import indicator | AG1: GeneralLedger | AH1: Omschrijving GB | AI1: Preferred | AJ1: SubAsset | AL1: AccountType,ShipTo,MaxAmt,MaterialGroup,DeliverTo,CommonIdDomain,ItemCategory,Asset,WBSElement,SAPPurchaseGroup,CurrForMinAndMaxAmt,AccountCategory,InternalOrder,CompanyCode,MinAmt,CommonId,GeneralLedger,Preferred,SubAsset
A2: 100 | C2: RO | F2: 4 | G2: Bloemen, planten en dieren | J2: Maak je keuze | K2: Boeketten, rouwkransen en kamerplanten | O2: 10000000 | Q2: unspsc | R2: M | Y2: A010 | AA2: 1015 | AB2: Boeketten, rouwkransen en kamerplanten | AC2: A1 | AD2: 0.06 | AE2: L | AI2: True | AL2: =""""&J2&""""&","&""""&L2&""""&","&""""&M2&""""&","&""""&O2&""""&","&""""&P2&""""&","&""""&Q2&""""&","&""""&R2&""""&","&""""&S2&""""&","&""""&T2&""""&","&""""&U2&""""&","&""""&V2&""""&","&""""&W2&""""&","&""""&X2&""""&","&""""&Y2&""""&","&""""&Z2&""""&","&""""&AA2&""""&","&""""&AG2&""""&","&""""&AI2&""""&","&""""&AJ2&""""&"" -> "Maak je keuze","","","10000000","","unspsc","M","","","","","","","A010","","1015","","True",""
A3: 100 | C3: RO | F3: 4 | G3: Bloemen, planten en dieren | H3: 17 | J3: Operationele werking | K3: Boeketten, rouwkransen en kamerplanten | O3: 10000000 | Q3: unspsc | R3: M | W3: K | Y3: A010 | AA3: 1015 | AB3: Boeketten, rouwkransen en kamerplanten | AC3: A1 | AD3: 0.06 | AE3: L | AG3: 6152000300 | AH3: Recepties/vergader | AI3: False | AL3: =""""&J3&""""&","&""""&L3&""""&","&""""&M3&""""&","&""""&O3&""""&","&""""&P3&""""&","&""""&Q3&""""&","&""""&R3&""""&","&""""&S3&""""&","&""""&T3&""""&","&""""&U3&""""&","&""""&V3&""""&","&""""&W3&""""&","&""""&X3&""""&","&""""&Y3&""""&","&""""&Z3&""""&","&""""&AA3&""""&","&""""&AG3&""""&","&""""&AI3&""""&","&""""&AJ3&""""&"" -> "Operationele werking","","","10000000","","unspsc","M","","","","","K","","A010","","1015","6152000300","False",""
A4: 100 | C4: RO | F4: 4 | G4: Bloemen, planten en dieren | H4: 3 | J4: Didactisch materiaal | K4: Boeketten, rouwkransen en kamerplanten | O4: 10000000 | Q4: unspsc | R4: M | W4: K | Y4: A010 | AA4: 1015 | AB4: Boeketten, rouwkransen en kamerplanten | AC4: A1 | AD4: 0.06 | AE4: L | AG4: 6161000200 | AH4: Didactisch materiaal | AI4: False | AL4: =""""&J4&""""&","&""""&L4&""""&","&""""&M4&""""&","&""""&O4&""""&","&""""&P4&""""&","&""""&Q4&""""&","&""""&R4&""""&","&""""&S4&""""&","&""""&T4&""""&","&""""&U4&""""&","&""""&V4&""""&","&""""&W4&""""&","&""""&X4&""""&","&""""&Y4&""""&","&""""&Z4&""""&","&""""&AA4&""""&","&""""&AG4&""""&","&""""&AI4&""""&","&""""&AJ4&""""&"" -> "Didactisch materiaal","","","10000000","","unspsc","M","","","","","K","","A010","","1015","6161000200","False",""
A5: 100 | C5: RO | F5: 4 | G5: Bloemen, planten en dieren | H5: 10 | J5: Representatie externen | K5: Boeketten, rouwkransen en kamerplanten | O5: 10000000 | Q5: unspsc | R5: M | W5: K | Y5: A010 | AA5: 1015 | AB5: Boeketten, rouwkransen en kamerplanten | AC5: A1 | AD5: 0.06 | AE5: L | AG5: 6146000400 | AH5: Representatiekosten | AI5: False | AL5: =""""&J5&""""&","&""""&L5&""""&","&""""&M5&""""&","&""""&O5&""""&","&""""&P5&""""&","&""""&Q5&""""&","&""""&R5&""""&","&""""&S5&""""&","&""""&T5&""""&","&""""&U5&""""&","&""""&V5&""""&","&""""&W5&""""&","&""""&X5&""""&","&""""&Y5&""""&","&""""&Z5&""""&","&""""&AA5&""""&","&""""&AG5&""""&","&""""&AI5&""""&","&""""&AJ5&""""&"" -> "Representatie externen","","","10000000","","unspsc","M","","","","","K","","A010","","1015","6146000400","False",""
A6: 200 | C6: intern | E6: 13_Zmaakjekeuze | F6: 4 | G6: Andere zaken | H6: 15 | J6: Doorrekening binnen AG SO | K6: Doorrekening binnen AG SO | O6: 10000000 | Q6: unspsc | R6: M | W6: K | Y6: A010 | AA6: 1015 | AB6: Boeketten, rouwkransen en kamerplanten | AC6: B0 | AD6: 0 | AE6: D | AG6: 4991000100 | AH6: Doorrek binnen AGSO | AI6: False | AL6: =""""&J6&""""&","&""""&L6&""""&","&""""&M6&""""&","&""""&O6&""""&","&""""&P6&""""&","&""""&Q6&""""&","&""""&R6&""""&","&""""&S6&""""&","&""""&T6&""""&","&""""&U6&""""&","&""""&V6&""""&","&""""&W6&""""&","&""""&X6&""""&","&""""&Y6&""""&","&""""&Z6&""""&","&""""&AA6&""""&","&""""&AG6&""""&","&""""&AI6&""""&","&""""&AJ6&""""&"" -> "Doorrekening binnen AG SO","","","10000000","","unspsc","M","","","","","K","","A010","","1015","4991000100","False",""
A7: 100 | C7: RO | F7: 4 | G7: Bloemen, planten en dieren | J7: Maak je keuze | K7: Bomen, planten en struiken | O7: 10000000 | Q7: unspsc | R7: M | Y7: A010 | AA7: 1016 | AB7: Bomen, planten en struiken | AC7: A1 | AD7: 0.06 | AE7: L | AI7: True | AL7: =""""&J7&""""&","&""""&L7&""""&","&""""&M7&""""&","&""""&O7&""""&","&""""&P7&""""&","&""""&Q7&""""&","&""""&R7&""""&","&""""&S7&""""&","&""""&T7&""""&","&""""&U7&""""&","&""""&V7&""""&","&""""&W7&""""&","&""""&X7&""""&","&""""&Y7&""""&","&""""&Z7&""""&","&""""&AA7&""""&","&""""&AG7&""""&","&""""&AI7&""""&","&""""&AJ7&""""&"" -> "Maak je keuze","","","10000000","","unspsc","M","","","","","","","A010","","1016","","True",""
A8: 100 | C8: RO | F8: 4 | G8: Bloemen, planten en dieren | H8: 17 | J8: Operationele werking | K8: Bomen, planten en struiken | O8: 10000000 | Q8: unspsc | R8: M | W8: K | Y8: A010 | AA8: 1016 | AB8: Bomen, planten en struiken | AC8: A1 | AD8: 0.06 | AE8: L | AG8: 6146000900 | AH8: Kantoorkosten | AI8: False | AL8: =""""&J8&""""&","&""""&L8&""""&","&""""&M8&""""&","&""""&O8&""""&","&""""&P8&""""&","&""""&Q8&""""&","&""""&R8&""""&","&""""&S8&""""&","&""""&T8&""""&","&""""&U8&""""&","&""""&V8&""""&","&""""&W8&""""&","&""""&X8&""""&","&""""&Y8&""""&","&""""&Z8&""""&","&""""&AA8&""""&","&""""&AG8&""""&","&""""&AI8&""""&","&""""&AJ8&""""&"" -> "Operationele werking","","","10000000","","unspsc","M","","","","","K","","A010","","1016","6146000900","False",""
A9: 100 | C9: RO | F9: 4 | G9: Bloemen, planten en dieren | H9: 2 | J9: Aankoop voor doorverkoop niet onderwijs | K9: Bomen, planten en struiken | O9: 10000000 | Q9: unspsc | R9: M | W9: K | Y9: A010 | AA9: 1016 | AB9: Bomen, planten en struiken | AC9: A1 | AD9: 0.06 | AE9: L | AG9: 6030000300 | AH9: Aank divers n ond | AI9: False | AL9: =""""&J9&""""&","&""""&L9&""""&","&""""&M9&""""&","&""""&O9&""""&","&""""&P9&""""&","&""""&Q9&""""&","&""""&R9&""""&","&""""&S9&""""&","&""""&T9&""""&","&""""&U9&""""&","&""""&V9&""""&","&""""&W9&""""&","&""""&X9&""""&","&""""&Y9&""""&","&""""&Z9&""""&","&""""&AA9&""""&","&""""&AG9&""""&","&""""&AI9&""""&","&""""&AJ9&""""&"" -> "Aankoop voor doorverkoop niet onderwijs","","","10000000","","unspsc","M","","","","","K","","A010","","1016","6030000300","False",""
A10: 100 | C10: RO | F10: 4 | G10: Bloemen, planten en dieren | H10: 3 | J10: Didactisch materiaal | K10: Bomen, planten en struiken | O10: 10000000 | Q10: unspsc | R10: M | W10: K | Y10: A010 | AA10: 1016 | AB10: Bomen, planten en struiken | AC10: A1 | AD10: 0.06 | AE10: L | AG10: 6161000200 | AH10: Didactisch materiaal | AI10: False | AL10: =""""&J10&""""&","&""""&L10&""""&","&""""&M10&""""&","&""""&O10&""""&","&""""&P10&""""&","&""""&Q10&""""&","&""""&R10&""""&","&""""&S10&""""&","&""""&T10&""""&","&""""&U10&""""&","&""""&V10&""""&","&""""&W10&""""&","&""""&X10&""""&","&""""&Y10&""""&","&""""&Z10&""""&","&""""&AA10&""""&","&""""&AG10&""""&","&""""&AI10&""""&","&""""&AJ10&""""&"" -> "Didactisch materiaal","","","10000000","","unspsc","M","","","","","K","","A010","","1016","6161000200","False",""
A11: 100 | C11: RO | F11: 4 | G11: Bloemen, planten en dieren | H11: 9 | J11: Investering | K11: Bomen, planten en struiken | O11: 10000000 | Q11: unspsc | R11: M | W11: A | Y11: A010 | AA11: 1016 | AB11: Bomen, planten en struiken | AC11: A1 | AD11: 0.06 | AE11: L | AG11: 2231000000 | AH11: VA erfp ond/werk | AI11: False | AL11: =""""&J11&""""&","&""""&L11&""""&","&""""&M11&""""&","&""""&O11&""""&","&""""&P11&""""&","&""""&Q11&""""&","&""""&R11&""""&","&""""&S11&""""&","&""""&T11&""""&","&""""&U11&""""&","&""""&V11&""""&","&""""&W11&""""&","&""""&X11&""""&","&""""&Y11&""""&","&""""&Z11&""""&","&""""&AA11&""""&","&""""&AG11&""""&","&""""&AI11&""""&","&""""&AJ11&""""&"" -> "Investering","","","10000000","","unspsc","M","","","","","A","","A010","","1016","2231000000","False",""
A12: 100 | C12: RO | F12: 4 | G12: Bloemen, planten en dieren | H12: 9 | J12: Doorrekening binnen AG SO | K12: Bomen, planten en struiken | O12: 10000000 | Q12: unspsc | R12: M | W12: K | Y12: A010 | AA12: 1016 | AB12: Bomen, planten en struiken | AC12: B0 | AD12: 0 | AE12: D | AG12: 4991000100 | AH12: Doorrek binnen AGSO | AI12: False | AL12: =""""&J12&""""&","&""""&L12&""""&","&""""&M12&""""&","&""""&O12&""""&","&""""&P12&""""&","&""""&Q12&""""&","&""""&R12&""""&","&""""&S12&""""&","&""""&T12&""""&","&""""&U12&""""&","&""""&V12&""""&","&""""&W12&""""&","&""""&X12&""""&","&""""&Y12&""""&","&""""&Z12&""""&","&""""&AA12&""""&","&""""&AG12&""""&","&""""&AI12&""""&","&""""&AJ12&""""&"" -> "Doorrekening binnen AG SO","","","10000000","","unspsc","M","","","","","K","","A010","","1016","4991000100","False",""
A13: 100 | C13: enkel adhoc | F13: 4 | G13: Bloemen, planten en dieren | J13: Maak je keuze | K13: Dierenbenodigdheden | O13: 10000000 | Q13: unspsc | R13: M | Y13: A010 | AA13: 1013 | AB13: Dieren en benodigdheden | AC13: A3 | AD13: 0.21 | AE13: L | AI13: True | AL13: =""""&J13&""""&","&""""&L13&""""&","&""""&M13&""""&","&""""&O13&""""&","&""""&P13&""""&","&""""&Q13&""""&","&""""&R13&""""&","&""""&S13&""""&","&""""&T13&""""&","&""""&U13&""""&","&""""&V13&""""&","&""""&W13&""""&","&""""&X13&""""&","&""""&Y13&""""&","&""""&Z13&""""&","&""""&AA13&""""&","&""""&AG13&""""&","&""""&AI13&""""&","&""""&AJ13&""""&"" -> "Maak je keuze","","","10000000","","unspsc","M","","","","","","","A010","","1013","","True",""
A14: 100 | C14: enkel adhoc | F14: 4 | G14: Bloemen, planten en dieren | H14: 17 | J14: Operationele werking | K14: Dierenbenodigdheden | O14: 10000000 | Q14: unspsc | R14: M | W14: K | Y14: A010 | AA14: 1013 | AB14: Dieren en benodigdheden | AC14: A3 | AD14: 0.21 | AE14: L | AG14: 6141100100 | AH14: Tech ben/gereeds RG | AI14: False | AL14: =""""&J14&""""&","&""""&L14&""""&","&""""&M14&""""&","&""""&O14&""""&","&""""&P14&""""&","&""""&Q14&""""&","&""""&R14&""""&","&""""&S14&""""&","&""""&T14&""""&","&""""&U14&""""&","&""""&V14&""""&","&""""&W14&""""&","&""""&X14&""""&","&""""&Y14&""""&","&""""&Z14&""""&","&""""&AA14&""""&","&""""&AG14&""""&","&""""&AI14&""""&","&""""&AJ14&""""&"" -> "Operationele werking","","","10000000","","unspsc","M","","","","","K","","A010","","1013","6141100100","False",""
A15: 100 | C15: enkel adhoc | F15: 4 | G15: Bloemen, planten en dieren | H15: 3 | J15: Didactisch materiaal | K15: Dierenbenodigdheden | O15: 10000000 | Q15: unspsc | R15: M | W15: K | Y15: A010 | AA15: 1013 | AB15: Dieren en benodigdheden | AC15: A3 | AD15: 0.21 | AE15: L | AG15: 6161000200 | AH15: Didactisch materiaal | AI15: False | AL15: =""""&J15&""""&","&""""&L15&""""&","&""""&M15&""""&","&""""&O15&""""&","&""""&P15&""""&","&""""&Q15&""""&","&""""&R15&""""&","&""""&S15&""""&","&""""&T15&""""&","&""""&U15&""""&","&""""&V15&""""&","&""""&W15&""""&","&""""&X15&""""&","&""""&Y15&""""&","&""""&Z15&""""&","&""""&AA15&""""&","&""""&AG15&""""&","&""""&AI15&""""&","&""""&AJ15&""""&"" -> "Didactisch materiaal","","","10000000","","unspsc","M","","","","","K","","A010","","1013","6161000200","False",""
A16: 100 | C16: RO | D16: 7 & 14 | F16: 7 | G16: Voertuigen & Transport | J16: Maak je keuze | K16: Aankoop/Huur rollend materieel | O16: 25000000 | Q16: unspsc | R16: M | Y16: A010 | AA16: 2510 | AB16: Aankoop rollend materieel (auto, fiets) | AC16: A3 | AD16: 0.21 | AE16: L | AI16: True | AL16: =""""&J16&""""&","&""""&L16&""""&","&""""&M16&""""&","&""""&O16&""""&","&""""&P16&""""&","&""""&Q16&""""&","&""""&R16&""""&","&""""&S16&""""&","&""""&T16&""""&","&""""&U16&""""&","&""""&V16&""""&","&""""&W16&""""&","&""""&X16&""""&","&""""&Y16&""""&","&""""&Z16&""""&","&""""&AA16&""""&","&""""&AG16&""""&","&""""&AI16&""""&","&""""&AJ16&""""&"" -> "Maak je keuze","","","25000000","","unspsc","M","","","","","","","A010","","2510","","True",""
A17: 100 | C17: RO | D17: 7 & 14 | F17: 7 | G17: Voertuigen & Transport | H17: 17 | J17: Operationele werking | K17: Aankoop/Huur rollend materieel | O17: 25000000 | Q17: unspsc | R17: M | W17: K | Y17: A010 | AA17: 2510 | AB17: Aankoop rollend materieel (auto, fiets) | AC17: A3 | AD17: 0.21 | AE17: L | AG17: 6142000100 | AH17: Leasing/huur voert | AI17: False | AL17: =""""&J17&""""&","&""""&L17&""""&","&""""&M17&""""&","&""""&O17&""""&","&""""&P17&""""&","&""""&Q17&""""&","&""""&R17&""""&","&""""&S17&""""&","&""""&T17&""""&","&""""&U17&""""&","&""""&V17&""""&","&""""&W17&""""&","&""""&X17&""""&","&""""&Y17&""""&","&""""&Z17&""""&","&""""&AA17&""""&","&""""&AG17&""""&","&""""&AI17&""""&","&""""&AJ17&""""&"" -> "Operationele werking","","","25000000","","unspsc","M","","","","","K","","A010","","2510","6142000100","False",""
A18: 100 | C18: RO | D18: 7 & 14 | F18: 7 | G18: Voertuigen & Transport | H18: 9 | J18: Investering | K18: Aankoop/Huur rollend materieel | O18: 25000000 | Q18: unspsc | R18: M | W18: A | Y18: A010 | AA18: 2510 | AB18: Aankoop rollend materieel (auto, fiets) | AC18: A3 | AD18: 0.21 | AE18: L | AG18: 2410000000 | AH18: Fietsen | AI18: False | AL18: =""""&J18&""""&","&""""&L18&""""&","&""""&M18&""""&","&""""&O18&""""&","&""""&P18&""""&","&""""&Q18&""""&","&""""&R18&""""&","&""""&S18&""""&","&""""&T18&""""&","&""""&U18&""""&","&""""&V18&""""&","&""""&W18&""""&","&""""&X18&""""&","&""""&Y18&""""&","&""""&Z18&""""&","&""""&AA18&""""&","&""""&AG18&""""&","&""""&AI18&""""&","&""""&AJ18&""""&"" -> "Investering","","","25000000","","unspsc","M","","","","","A","","A010","","2510","2410000000","False",""
A19: 100 | C19: enkel adhoc | F19: 14 | G19: FD | J19: Maak je keuze | O19: 27000000 | Q19: unspsc | R19: M | Y19: A010 | AA19: 2712 | AB19: Technisch materiaal - aangedreven gereedschap | AC19: A3 | AD19: 0.21 | AE19: L | AI19: True | AL19: =""""&J19&""""&","&""""&L19&""""&","&""""&M19&""""&","&""""&O19&""""&","&""""&P19&""""&","&""""&Q19&""""&","&""""&R19&""""&","&""""&S19&""""&","&""""&T19&""""&","&""""&U19&""""&","&""""&V19&""""&","&""""&W19&""""&","&""""&X19&""""&","&""""&Y19&""""&","&""""&Z19&""""&","&""""&AA19&""""&","&""""&AG19&""""&","&""""&AI19&""""&","&""""&AJ19&""""&"" -> "Maak je keuze","","","27000000","","unspsc","M","","","","","","","A010","","2712","","True",""
A20: 100 | C20: enkel adhoc | F20: 14 | G20: FD | H20: 17 | J20: Operationele werking | O20: 27000000 | Q20: unspsc | R20: M | W20: K | Y20: A010 | AA20: 2712 | AB20: Technisch materiaal - aangedreven gereedschap | AC20: A3 | AD20: 0.21 | AE20: L | AG20: 6141100100 | AH20: Tech ben/gereeds RG | AI20: False | AL20: =""""&J20&""""&","&""""&L20&""""&","&""""&M20&""""&","&""""&O20&""""&","&""""&P20&""""&","&""""&Q20&""""&","&""""&R20&""""&","&""""&S20&""""&","&""""&T20&""""&","&""""&U20&""""&","&""""&V20&""""&","&""""&W20&""""&","&""""&X20&""""&","&""""&Y20&""""&","&""""&Z20&""""&","&""""&AA20&""""&","&""""&AG20&""""&","&""""&AI20&""""&","&""""&AJ20&""""&"" -> "Operationele werking","","","27000000","","unspsc","M","","","","","K","","A010","","2712","6141100100","False",""
A21: 100 | B21: Dit unspsc evengoed gebruiken voor de lasercutters en de 3D printers | C21: enkel adhoc | F21: 14 | G21: FD | H21: 9 | J21: Investering | O21: 27000000 | Q21: unspsc | R21: M | W21: A | Y21: A010 | AA21: 2712 | AB21: Technisch materiaal - aangedreven gereedschap | AC21: A3 | AD21: 0.21 | AE21: L | AG21: 2301000000 | AH21: Mach en gereed | AI21: False | AL21: =""""&J21&""""&","&""""&L21&""""&","&""""&M21&""""&","&""""&O21&""""&","&""""&P21&""""&","&""""&Q21&""""&","&""""&R21&""""&","&""""&S21&""""&","&""""&T21&""""&","&""""&U21&""""&","&""""&V21&""""&","&""""&W21&""""&","&""""&X21&""""&","&""""&Y21&""""&","&""""&Z21&""""&","&""""&AA21&""""&","&""""&AG21&""""&","&""""&AI21&""""&","&""""&AJ21&""""&"" -> "Investering","","","27000000","","unspsc","M","","","","","A","","A010","","2712","2301000000","False",""
A22: 100 | B22: van tegel 5 naar 6 overgebracht; ook in 14 aanwezig | C22: RO | F22: 14 | G22: FD | J22: Maak je keuze | O22: 27000000 | Q22: unspsc | R22: M | Y22: A010 | AA22: 27 | AB22: Technisch materiaal - kleine machines en gereedschappen | AC22: A3 | AD22: 0.21 | AE22: L | AI22: True | AL22: =""""&J22&""""&","&""""&L22&""""&","&""""&M22&""""&","&""""&O22&""""&","&""""&P22&""""&","&""""&Q22&""""&","&""""&R22&""""&","&""""&S22&""""&","&""""&T22&""""&","&""""&U22&""""&","&""""&V22&""""&","&""""&W22&""""&","&""""&X22&""""&","&""""&Y22&""""&","&""""&Z22&""""&","&""""&AA22&""""&","&""""&AG22&""""&","&""""&AI22&""""&","&""""&AJ22&""""&"" -> "Maak je keuze","","","27000000","","unspsc","M","","","","","","","A010","","27","","True",""
A23: 100 | B23: van tegel 5 naar 6 overgebracht; ook in 14 aanwezig | C23: RO | D23: 6 & 14 | F23: 14 | G23: FD | H23: 17 | J23: Operationele werking | O23: 27000000 | Q23: unspsc | R23: M | W23: K | Y23: A010 | AA23: 27 | AB23: Technisch materiaal - kleine machines en gereedschappen | AC23: A3 | AD23: 0.21 | AE23: L | AG23: 6141100100 | AH23: Tech ben/gereeds RG | AI23: False | AL23: =""""&J23&""""&","&""""&L23&""""&","&""""&M23&""""&","&""""&O23&""""&","&""""&P23&""""&","&""""&Q23&""""&","&""""&R23&""""&","&""""&S23&""""&","&""""&T23&""""&","&""""&U23&""""&","&""""&V23&""""&","&""""&W23&""""&","&""""&X23&""""&","&""""&Y23&""""&","&""""&Z23&""""&","&""""&AA23&""""&","&""""&AG23&""""&","&""""&AI23&""""&","&""""&AJ23&""""&"" -> "Operationele werking","","","27000000","","unspsc","M","","","","","K","","A010","","27","6141100100","False",""
A24: 100 | B24: van tegel 5 naar 6 overgebracht; ook in 14 aanwezig | C24: RO | D24: 6 & 14 | F24: 14 | G24: FD | H24: 9 | J24: Investering | O24: 27000000 | Q24: unspsc | R24: M | W24: A | Y24: A010 | AA24: 27 | AB24: Technisch materiaal - kleine machines en gereedschappen | AC24: A3 | AD24: 0.21 | AE24: L | AG24: 2301000000 | AH24: Mach en gereed | AI24: False | AL24: =""""&J24&""""&","&""""&L24&""""&","&""""&M24&""""&","&""""&O24&""""&","&""""&P24&""""&","&""""&Q24&""""&","&""""&R24&""""&","&""""&S24&""""&","&""""&T24&""""&","&""""&U24&""""&","&""""&V24&""""&","&""""&W24&""""&","&""""&X24&""""&","&""""&Y24&""""&","&""""&Z24&""""&","&""""&AA24&""""&","&""""&AG24&""""&","&""""&AI24&""""&","&""""&AJ24&""""&"" -> "Investering","","","27000000","","unspsc","M","","","","","A","","A010","","27","2301000000","False",""
A25: 100 | C25: enkel adhoc | D25: 6&14 | E25: 6_Zmaakjekeuze | F25: 6 | G25: Bouw en techniek | J25: Maak je keuze | K25: Onderhoud en herstelling gebouw | O25: 30000000 | Q25: unspsc | R25: M | Y25: A010 | AA25: 30 | AB25: Bouw- en afwerkingsmaterialen 21% | AC25: A3 | AD25: 0.21 | AE25: L | AI25: True | AL25: =""""&J25&""""&","&""""&L25&""""&","&""""&M25&""""&","&""""&O25&""""&","&""""&P25&""""&","&""""&Q25&""""&","&""""&R25&""""&","&""""&S25&""""&","&""""&T25&""""&","&""""&U25&""""&","&""""&V25&""""&","&""""&W25&""""&","&""""&X25&""""&","&""""&Y25&""""&","&""""&Z25&""""&","&""""&AA25&""""&","&""""&AG25&""""&","&""""&AI25&""""&","&""""&AJ25&""""&"" -> "Maak je keuze","","","30000000","","unspsc","M","","","","","","","A010","","30","","True",""
A26: 100 | B26: overal unspsc 30 gebruiken - tegel 6 als 14- identiek GB& Accounttype als bij 31 (31 mag weg) | C26: RO | E26: 6_Zmaakjekeuze | F26: 6 | G26: Bouw en techniek | H26: 17 | J26: Operationele werking | K26: Onderhoud en herstelling gebouw | O26: 30000000 | Q26: unspsc | R26: M | W26: K | Y26: A010 | AA26: 30 | AB26: Bouw- en afwerkingsmaterialen 21% | AC26: A3 | AD26: 0.21 | AE26: L | AG26: 6141100100 | AH26: Tech ben/gereeds RG | AI26: False | AL26: =""""&J26&""""&","&""""&L26&""""&","&""""&M26&""""&","&""""&O26&""""&","&""""&P26&""""&","&""""&Q26&""""&","&""""&R26&""""&","&""""&S26&""""&","&""""&T26&""""&","&""""&U26&""""&","&""""&V26&""""&","&""""&W26&""""&","&""""&X26&""""&","&""""&Y26&""""&","&""""&Z26&""""&","&""""&AA26&""""&","&""""&AG26&""""&","&""""&AI26&""""&","&""""&AJ26&""""&"" -> "Operationele werking","","","30000000","","unspsc","M","","","","","K","","A010","","30","6141100100","False",""
A27: 100 | B27: overal unspsc 30 gebruiken - tegel 6 als 14- identiek GB& Accounttype als bij 31 (31 mag weg) | C27: RO | E27: 6_Zmaakjekeuze | F27: 6 | G27: Bouw en techniek | H27: 9 | J27: Investering | K27: Onderhoud en herstelling gebouw | O27: 30000000 | Q27: unspsc | R27: M | W27: A | Y27: A010 | AA27: 30 | AB27: Bouw- en afwerkingsmaterialen 21% | AC27: A3 | AD27: 0.21 | AE27: L | AG27: 2301000000 | AH27: Mach en gereed | AI27: False | AL27: =""""&J27&""""&","&""""&L27&""""&","&""""&M27&""""&","&""""&O27&""""&","&""""&P27&""""&","&""""&Q27&""""&","&""""&R27&""""&","&""""&S27&""""&","&""""&T27&""""&","&""""&U27&""""&","&""""&V27&""""&","&""""&W27&""""&","&""""&X27&""""&","&""""&Y27&""""&","&""""&Z27&""""&","&""""&AA27&""""&","&""""&AG27&""""&","&""""&AI27&""""&","&""""&AJ27&""""&"" -> "Investering","","","30000000","","unspsc","M","","","","","A","","A010","","30","2301000000","False",""
A28: 100 | C28: RO | E28: 14_Zmaakjekeuze | F28: 14 | G28: FD | J28: Maak je keuze | O28: 31000000 | Q28: unspsc | R28: M | Y28: A010 | AA28: 31 | AB28: Technisch materiaal - bouw en afwerkingsmaterialen 6% | AC28: A1 | AD28: 0.06 | AE28: L | AI28: True | AL28: =""""&J28&""""&","&""""&L28&""""&","&""""&M28&""""&","&""""&O28&""""&","&""""&P28&""""&","&""""&Q28&""""&","&""""&R28&""""&","&""""&S28&""""&","&""""&T28&""""&","&""""&U28&""""&","&""""&V28&""""&","&""""&W28&""""&","&""""&X28&""""&","&""""&Y28&""""&","&""""&Z28&""""&","&""""&AA28&""""&","&""""&AG28&""""&","&""""&AI28&""""&","&""""&AJ28&""""&"" -> "Maak je keuze","","","31000000","","unspsc","M","","","","","","","A010","","31","","True",""
A29: 100 | C29: RO | E29: 14_Zmaakjekeuze | F29: 14 | G29: FD | H29: 17 | J29: Operationele werking | O29: 31000000 | Q29: unspsc | R29: M | W29: K | Y29: A010 | AA29: 31 | AB29: Technisch materiaal - bouw en afwerkingsmaterialen 6% | AC29: A1 | AD29: 0.06 | AE29: L | AG29: 6141100100 | AH29: Tech ben/gereeds RG | AI29: False | AL29: =""""&J29&""""&","&""""&L29&""""&","&""""&M29&""""&","&""""&O29&""""&","&""""&P29&""""&","&""""&Q29&""""&","&""""&R29&""""&","&""""&S29&""""&","&""""&T29&""""&","&""""&U29&""""&","&""""&V29&""""&","&""""&W29&""""&","&""""&X29&""""&","&""""&Y29&""""&","&""""&Z29&""""&","&""""&AA29&""""&","&""""&AG29&""""&","&""""&AI29&""""&","&""""&AJ29&""""&"" -> "Operationele werking","","","31000000","","unspsc","M","","","","","K","","A010","","31","6141100100","False",""
A30: 100 | C30: RO | E30: 14_Zmaakjekeuze | F30: 14 | G30: FD | H30: 9 | J30: Investering | O30: 31000000 | Q30: unspsc | R30: M | W30: A | Y30: A010 | AA30: 31 | AB30: Technisch materiaal - bouw en afwerkingsmaterialen 6% | AC30: A1 | AD30: 0.06 | AE30: L | AG30: 2301000000 | AH30: Mach en gereed | AI30: False | AL30: =""""&J30&""""&","&""""&L30&""""&","&""""&M30&""""&","&""""&O30&""""&","&""""&P30&""""&","&""""&Q30&""""&","&""""&R30&""""&","&""""&S30&""""&","&""""&T30&""""&","&""""&U30&""""&","&""""&V30&""""&","&""""&W30&""""&","&""""&X30&""""&","&""""&Y30&""""&","&""""&Z30&""""&","&""""&AA30&""""&","&""""&AG30&""""&","&""""&AI30&""""&","&""""&AJ30&""""&"" -> "Investering","","","31000000","","unspsc","M","","","","","A","","A010","","31","2301000000","False",""
A31: 100 | C31: RO | D31: 6 & 14 | F31: 14 | G31: FD | J31: Maak je keuze | O31: 39000000 | Q31: unspsc | R31: M | Y31: A010 | AA31: 39 | AB31: Technisch materiaal - elektriciteit | AC31: A3 | AD31: 0.21 | AE31: L | AI31: True | AL31: =""""&J31&""""&","&""""&L31&""""&","&""""&M31&""""&","&""""&O31&""""&","&""""&P31&""""&","&""""&Q31&""""&","&""""&R31&""""&","&""""&S31&""""&","&""""&T31&""""&","&""""&U31&""""&","&""""&V31&""""&","&""""&W31&""""&","&""""&X31&""""&","&""""&Y31&""""&","&""""&Z31&""""&","&""""&AA31&""""&","&""""&AG31&""""&","&""""&AI31&""""&","&""""&AJ31&""""&"" -> "Maak je keuze","","","39000000","","unspsc","M","","","","","","","A010","","39","","True",""
A32: 100 | C32: RO | D32: 6 & 14 | F32: 14 | G32: FD | H32: 17 | J32: Operationele werking | O32: 39000000 | Q32: unspsc | R32: M | W32: K | Y32: A010 | AA32: 39 | AB32: Technisch materiaal - elektriciteit | AC32: A3 | AD32: 0.21 | AE32: L | AG32: 6141100100 | AH32: Tech ben/gereeds RG | AI32: False | AL32: =""""&J32&""""&","&""""&L32&""""&","&""""&M32&""""&","&""""&O32&""""&","&""""&P32&""""&","&""""&Q32&""""&","&""""&R32&""""&","&""""&S32&""""&","&""""&T32&""""&","&""""&U32&""""&","&""""&V32&""""&","&""""&W32&""""&","&""""&X32&""""&","&""""&Y32&""""&","&""""&Z32&""""&","&""""&AA32&""""&","&""""&AG32&""""&","&""""&AI32&""""&","&""""&AJ32&""""&"" -> "Operationele werking","","","39000000","","unspsc","M","","","","","K","","A010","","39","6141100100","False",""
A33: 100 | C33: RO | D33: 6 & 14 | F33: 14 | G33: FD | H33: 9 | J33: Investering | O33: 39000000 | Q33: unspsc | R33: M | W33: A | Y33: A010 | AA33: 39 | AB33: Technisch materiaal - elektriciteit | AC33: A3 | AD33: 0.21 | AE33: L | AG33: 2301000000 | AH33: Mach en gereed | AI33: False | AL33: =""""&J33&""""&","&""""&L33&""""&","&""""&M33&""""&","&""""&O33&""""&","&""""&P33&""""&","&""""&Q33&""""&","&""""&R33&""""&","&""""&S33&""""&","&""""&T33&""""&","&""""&U33&""""&","&""""&V33&""""&","&""""&W33&""""&","&""""&X33&""""&","&""""&Y33&""""&","&""""&Z33&""""&","&""""&AA33&""""&","&""""&AG33&""""&","&""""&AI33&""""&","&""""&AJ33&""""&"" -> "Investering","","","39000000","","unspsc","M","","","","","A","","A010","","39","2301000000","False",""
A34: 100 | B34: Unspsc 4015 voorzien in adhoc- installaties maar algemeen, geen specificatie van de installatie=> unspsc 4015 Aankoop/ huur installatie | C34: RO | F34: 14 | G34: FD | J34: Maak je keuze | O34: 40000000 | Q34: unspsc | R34: M | Y34: A010 | AA34: 4015 | AB34: Aankoop installatie | AC34: B3 | AD34: 0.21 | AE34: D | AI34: True | AL34: =""""&J34&""""&","&""""&L34&""""&","&""""&M34&""""&","&""""&O34&""""&","&""""&P34&""""&","&""""&Q34&""""&","&""""&R34&""""&","&""""&S34&""""&","&""""&T34&""""&","&""""&U34&""""&","&""""&V34&""""&","&""""&W34&""""&","&""""&X34&""""&","&""""&Y34&""""&","&""""&Z34&""""&","&""""&AA34&""""&","&""""&AG34&""""&","&""""&AI34&""""&","&""""&AJ34&""""&"" -> "Maak je keuze","","","40000000","","unspsc","M","","","","","","","A010","","4015","","True",""
A35: 100 | B35: Unspsc 4015 voorzien in adhoc- installaties maar algemeen, geen specificatie van de installatie=> unspsc 4015 Aankoop/ huur installatie | C35: RO | F35: 14 | G35: FD | H35: 17 | J35: Operationele werking | O35: 40000000 | Q35: unspsc | R35: M | W35: K | Y35: A010 | AA35: 4015 | AB35: Aankoop installatie | AC35: B3 | AD35: 0.21 | AE35: D | AG35: 6141000100 | AH35: Leasing/huur RG nrol | AI35: False | AL35: =""""&J35&""""&","&""""&L35&""""&","&""""&M35&""""&","&""""&O35&""""&","&""""&P35&""""&","&""""&Q35&""""&","&""""&R35&""""&","&""""&S35&""""&","&""""&T35&""""&","&""""&U35&""""&","&""""&V35&""""&","&""""&W35&""""&","&""""&X35&""""&","&""""&Y35&""""&","&""""&Z35&""""&","&""""&AA35&""""&","&""""&AG35&""""&","&""""&AI35&""""&","&""""&AJ35&""""&"" -> "Operationele werking","","","40000000","","unspsc","M","","","","","K","","A010","","4015","6141000100","False",""
A36: 100 | B36: Unspsc 4015 voorzien in adhoc- installaties maar algemeen, geen specificatie van de installatie=> unspsc 4015 Aankoop/ huur installatie | C36: RO | F36: 14 | G36: FD | H36: 9 | J36: Investering | O36: 40000000 | Q36: unspsc | R36: M | W36: A | Y36: A010 | AA36: 4015 | AB36: Aankoop installatie | AC36: B3 | AD36: 0.21 | AE36: D | AG36: 2300000000 | AH36: Ins/ma/uitr | AI36: False | AL36: =""""&J36&""""&","&""""&L36&""""&","&""""&M36&""""&","&""""&O36&""""&","&""""&P36&""""&","&""""&Q36&""""&","&""""&R36&""""&","&""""&S36&""""&","&""""&T36&""""&","&""""&U36&""""&","&""""&V36&""""&","&""""&W36&""""&","&""""&X36&""""&","&""""&Y36&""""&","&""""&Z36&""""&","&""""&AA36&""""&","&""""&AG36&""""&","&""""&AI36&""""&","&""""&AJ36&""""&"" -> "Investering","","","40000000","","unspsc","M","","","","","A","","A010","","4015","2300000000","False",""
A37: 100 | C37: RO | F37: 5 | G37: Elektrotoestellen, machines en gereedschappen | J37: Maak je keuze | K37: ICT- materiaal | O37: 43000000 | Q37: unspsc | R37: M | Y37: A010 | AA37: 43211720 | AB37: Betaalterminaal | AC37: A3 | AD37: 0.21 | AE37: L | AI37: True | AL37: =""""&J37&""""&","&""""&L37&""""&","&""""&M37&""""&","&""""&O37&""""&","&""""&P37&""""&","&""""&Q37&""""&","&""""&R37&""""&","&""""&S37&""""&","&""""&T37&""""&","&""""&U37&""""&","&""""&V37&""""&","&""""&W37&""""&","&""""&X37&""""&","&""""&Y37&""""&","&""""&Z37&""""&","&""""&AA37&""""&","&""""&AG37&""""&","&""""&AI37&""""&","&""""&AJ37&""""&"" -> "Maak je keuze","","","43000000","","unspsc","M","","","","","","","A010","","43211720","","True",""
A38: 100 | C38: RO | F38: 5 | G38: Elektrotoestellen, machines en gereedschappen | H38: 17 | J38: Operationele werking | K38: ICT- materiaal | O38: 43000000 | Q38: unspsc | R38: M | W38: K | Y38: A010 | AA38: 43211720 | AB38: Betaalterminaal | AC38: A3 | AD38: 0.21 | AE38: L | AG38: 6141000100 | AH38: Leasing/huur RG nrol | AI38: False | AL38: =""""&J38&""""&","&""""&L38&""""&","&""""&M38&""""&","&""""&O38&""""&","&""""&P38&""""&","&""""&Q38&""""&","&""""&R38&""""&","&""""&S38&""""&","&""""&T38&""""&","&""""&U38&""""&","&""""&V38&""""&","&""""&W38&""""&","&""""&X38&""""&","&""""&Y38&""""&","&""""&Z38&""""&","&""""&AA38&""""&","&""""&AG38&""""&","&""""&AI38&""""&","&""""&AJ38&""""&"" -> "Operationele werking","","","43000000","","unspsc","M","","","","","K","","A010","","43211720","6141000100","False",""
A39: 100 | C39: RO | F39: 5 | G39: Elektrotoestellen, machines en gereedschappen | H39: 9 | J39: Investering | K39: ICT- materiaal | O39: 43000000 | Q39: unspsc | R39: M | W39: A | Y39: A010 | AA39: 43211720 | AB39: Betaalterminaal | AC39: A3 | AD39: 0.21 | AE39: L | AG39: 2301000000 | AH39: Mach en gereed | AI39: False | AL39: =""""&J39&""""&","&""""&L39&""""&","&""""&M39&""""&","&""""&O39&""""&","&""""&P39&""""&","&""""&Q39&""""&","&""""&R39&""""&","&""""&S39&""""&","&""""&T39&""""&","&""""&U39&""""&","&""""&V39&""""&","&""""&W39&""""&","&""""&X39&""""&","&""""&Y39&""""&","&""""&Z39&""""&","&""""&AA39&""""&","&""""&AG39&""""&","&""""&AI39&""""&","&""""&AJ39&""""&"" -> "Investering","","","43000000","","unspsc","M","","","","","A","","A010","","43211720","2301000000","False",""
A40: 100 | C40: RO | F40: 5 | G40: Elektrotoestellen, machines en gereedschappen | J40: Maak je keuze | K40: ICT- materiaal | O40: 43000000 | Q40: unspsc | R40: M | Y40: A010 | AA40: 43211699 | AB40: IT randapparatuur en multimedia, klein ict incl. 2de hands | AC40: A3 | AD40: 0.21 | AE40: L | AI40: True | AL40: =""""&J40&""""&","&""""&L40&""""&","&""""&M40&""""&","&""""&O40&""""&","&""""&P40&""""&","&""""&Q40&""""&","&""""&R40&""""&","&""""&S40&""""&","&""""&T40&""""&","&""""&U40&""""&","&""""&V40&""""&","&""""&W40&""""&","&""""&X40&""""&","&""""&Y40&""""&","&""""&Z40&""""&","&""""&AA40&""""&","&""""&AG40&""""&","&""""&AI40&""""&","&""""&AJ40&""""&"" -> "Maak je keuze","","","43000000","","unspsc","M","","","","","","","A010","","43211699","","True",""
...

Sheet Blad2
A1: NR TEGEL | B1: TEGELNAAM | C1: LEVEL 2 | D1: Omschrijving tegel | E1: AccountType | F1: Grootboekrekening | G1: Omschrijving GB | H1: Budgetpositie | I1: btw-code
A2: 1 | B2: Eten en drinken | C2: Dranken | D2: Alcoholische dranken | E2: Didactisch materiaal | F2: 6161000200 | G2: Didactisch materiaal | H2: =VLOOKUP(F2,Blad3!$1:$1048576,3,FALSE) -> 61612000 | I2: 0.21
A3: 1 | B3: Eten en drinken | C3: Dranken | D3: Alcoholische dranken | E3: Evenementen (bv infodagen & personeelsfeest) | F3: 6151000400 | G3: Evenementen | H3: =VLOOKUP(F3,Blad3!$1:$1048576,3,FALSE) -> 61510000 | I3: 0.21
A4: 1 | B4: Eten en drinken | C4: Dranken | D4: Alcoholische dranken | E4: Recepties & vergaderingen personeel / leerlingen | F4: 6152000300 | G4: Recepties/vergader | H4: =VLOOKUP(F4,Blad3!$1:$1048576,3,FALSE) -> 61530000 | I4: 0.21
A5: 1 | B5: Eten en drinken | C5: Dranken | D5: Alcoholische dranken | E5: Doorverkoop onderwijs (niet max fac) | F5: 6030000200 | G5: Niet maximumfactuur | H5: =VLOOKUP(F5,Blad3!$1:$1048576,3,FALSE) -> 60320000 | I5: 0.21
A6: 1 | B6: Eten en drinken | C6: Voeding | D6: Alcoholische dranken | E6: Representatie externen | F6: 6146000400 | G6: Representatiekosten | H6: =VLOOKUP(F6,Blad3!$1:$1048576,3,FALSE) -> 61460000 | I6: 0.21
A7: 1 | B7: Eten en drinken | C7: Voeding | D7: Alcoholische dranken | E7: Teambuilding | F7: 6152000200 | G7: Personeelsactiviteit | H7: =VLOOKUP(F7,Blad3!$1:$1048576,3,FALSE) -> 61520002 | I7: 0.21
A8: 1 | B8: Eten en drinken | C8: Eten | D8: Broodjes | E8: Recepties & vergaderingen personeel / leerlingen | F8: 6152000300 | G8: Recepties/vergader | H8: =VLOOKUP(F8,Blad3!$1:$1048576,3,FALSE) -> 61530000 | I8: 0.06
A9: 1 | B9: Eten en drinken | C9: Eten | D9: Broodjes | E9: Aankoop voor doorverkoop niet onderwijs | F9: 6030000300 | G9: Aank divers n ond | H9: =VLOOKUP(F9,Blad3!$1:$1048576,3,FALSE) -> 60330000 | I9: 0.06
A10: 1 | B10: Eten en drinken | C10: Eten | D10: Broodjes | E10: Didactisch materiaal | F10: 6161000200 | G10: Didactisch materiaal | H10: =VLOOKUP(F10,Blad3!$1:$1048576,3,FALSE) -> 61612000 | I10: 0.06
A11: 1 | B11: Eten en drinken | C11: Eten | D11: Broodjes | E11: Evenementen (bv infodagen & personeelsfeest) | F11: 6151000400 | G11: Evenementen | H11: =VLOOKUP(F11,Blad3!$1:$1048576,3,FALSE) -> 61510000 | I11: 0.06
A12: 1 | B12: Eten en drinken | C12: Eten | D12: Broodjes | E12: Representatie externen | F12: 6146000400 | G12: Representatiekosten | H12: =VLOOKUP(F12,Blad3!$1:$1048576,3,FALSE) -> 61460000 | I12: 0.06
A13: 1 | B13: Eten en drinken | C13: Eten | D13: Broodjes | E13: Nascholing | F13: 6152000100 | G13: Opleidingskosten | H13: =VLOOKUP(F13,Blad3!$1:$1048576,3,FALSE) -> 61520001 | I13: 0.06
... A174: 4 | B174: Bloemen, planten en dieren | C174: Boeketten, rouwkransen en kamerplanten | D174: Boeketten, rouwkransen en kamerplanten | E174: Representatie externen | F174: 6146000400 | G174: Representatiekosten | H174: =VLOOKUP(F174,Blad3!$1:$1048576,3,FALSE) -> 61460000 | I174: 0.06
A175: 4 | B175: Andere zaken | C175: Doorrekening binnen AG SO | D175: Boeketten, rouwkransen en kamerplanten | E175: Doorrekening binnen AG SO | F175: 4991000100 | G175: Doorrek binnen AGSO | I175: 0
A176: 4 | B176: Bloemen, planten en dieren | C176: Bomen, planten en struiken | D176: Bomen, planten en struiken | E176: Operationele werking | F176: 6146000900 | G176: Kantoorkosten | H176: =VLOOKUP(F176,Blad3!$1:$1048576,3,FALSE) -> 61490000 | I176: 0.06
A177: 4 | B177: Bloemen, planten en dieren | C177: Bomen, planten en struiken | D177: Bomen, planten en struiken | E177: Aankoop voor doorverkoop niet onderwijs | F177: 6030000300 | G177: Aank divers n ond | H177: =VLOOKUP(F177,Blad3!$1:$1048576,3,FALSE) -> 60330000 | I177: 0.06
A178: 4 | B178: Bloemen, planten en dieren | C178: Bomen, planten en struiken | D178: Bomen, planten en struiken | E178: Didactisch materiaal | F178: 6161000200 | G178: Didactisch materiaal | H178: =VLOOKUP(F178,Blad3!$1:$1048576,3,FALSE) -> 61612000 | I178: 0.06
A179: 4 | B179: Bloemen, planten en dieren | C179: Bomen, planten en struiken | D179: Bomen, planten en struiken | E179: Investering | F179: 2231000000 | G179: VA erfp ond/werk | H179: =VLOOKUP(F179,Blad3!$1:$1048576,3,FALSE) -> 22310000 | I179: 0.06
A180: 4 | B180: Bloemen, planten en dieren | C180: Bomen, planten en struiken | D180: Bomen, planten en struiken | E180: Doorrekening binnen AG SO | F180: 4991000100 | G180: Doorrek binnen AGSO | I180: 0
A181: 4 | B181: Bloemen, planten en dieren | C181: Dierenbenodigdheden | D181: Dieren en benodigdheden | E181: Operationele werking | F181: 6141100100 | G181: Tech ben/gereeds RG | H181: =VLOOKUP(F181,Blad3!$1:$1048576,3,FALSE) -> 61411000 | I181: 0.21
A182: 4 | B182: Bloemen, planten en dieren | C182: Dierenbenodigdheden | D182: Dieren en benodigdheden | E182: Didactisch materiaal | F182: 6161000200 | G182: Didactisch materiaal | H182: =VLOOKUP(F182,Blad3!$1:$1048576,3,FALSE) -> 61612000 | I182: 0.21
A183: 4 | B183: Bloemen, planten en dieren | C183: Tuin- en landbouw producten | D183: Tuin- en landbouw producten | E183: Didactisch materiaal | F183: 6161000200 | G183: Didactisch materiaal | H183: =VLOOKUP(F183,Blad3!$1:$1048576,3,FALSE) -> 61612000 | I183: 0.21
A184: 5 | B184: Elektrotoestellen, machines en gereedschappen | C184: ICT- materiaal | D184: Betaalterminaal | E184: Operationele werking | F184: 6141000100 | G184: Leasing/huur RG nrol | H184: =VLOOKUP(F184,Blad3!$1:$1048576,3,FALSE) -> 61410000 | I184: 0.21
A185: 5 | B185: Elektrotoestellen, machines en gereedschappen | C185: ICT- materiaal | D185: Betaalterminaal | E185: Investering | F185: 2301000000 | G185: Mach en gereed | H185: =VLOOKUP(F185,Blad3!$1:$1048576,3,FALSE) -> 23010000 | I185: 0.21
A186: 5 | B186: Elektrotoestellen, machines en gereedschappen | C186: ICT- materiaal | D186: IT randapparatuur en multimedia, klein ict incl. 2de hands | E186: Operationele werking | F186: 6146000900 | G186: Kantoorkosten | H186: =VLOOKUP(F186,Blad3!$1:$1048576,3,FALSE) -> 61490000 | I186: 0.21
A187: 5 | B187: Elektrotoestellen, machines en gereedschappen | C187: ICT- materiaal | D187: IT randapparatuur en multimedia, klein ict incl. 2de hands | E187: Investering | F187: 2402000000 | G187: Informatica mat | H187: =VLOOKUP(F187,Blad3!$1:$1048576,3,FALSE) -> 24020000 | I187: 0.21
A188: 5 | B188: Elektrotoestellen, machines en gereedschappen | C188: ICT- materiaal | D188: Sofwarelicenties scholen | E188: Didactisch materiaal | F188: 6161000200 | G188: Didactisch materiaal | H188: =VLOOKUP(F188,Blad3!$1:$1048576,3,FALSE) -> 61612000 | I188: 0.21
A189: 5 | B189: Elektrotoestellen, machines en gereedschappen | C189: ICT- materiaal | D189: Sofwarelicenties scholen | E189: Investering | F189: 2110000000 | G189: Conc oct lic kh | H189: =VLOOKUP(F189,Blad3!$1:$1048576,3,FALSE) -> 21100000 | I189: 0.21
A190: 5 | B190: Elektrotoestellen, machines en gereedschappen | C190: ICT- materiaal | D190: Sofwarelicenties scholen (niet pedagogisch) | E190: Operationele werking | F190: 6146000900 | G190: Kantoorkosten | H190: =VLOOKUP(F190,Blad3!$1:$1048576,3,FALSE) -> 61490000 | I190: 0.21
A191: 5 | B191: Elektrotoestellen, machines en gereedschappen | C191: ICT- materiaal | D191: Sofwarelicenties scholen buitenlandse leverancier | E191: Didactisch materiaal | F191: 6161000200 | G191: Didactisch materiaal | H191: =VLOOKUP(F191,Blad3!$1:$1048576,3,FALSE) -> 61612000 | I191: 0.21
A192: 5 | B192: Elektrotoestellen, machines en gereedschappen | C192: ICT- materiaal | D192: Sofwarelicenties scholen buitenlandse leverancier | E192: Investering | F192: 2110000000 | G192: Conc oct lic kh | H192: =VLOOKUP(F192,Blad3!$1:$1048576,3,FALSE) -> 21100000 | I192: 0.21
... A199: 5 | B199: Elektrotoestellen, machines en gereedschappen | C199: Huishoudtoestellen | D199: Huishoud- en industriële toestellen | E199: Operationele werking | F199: 6141100100 | G199: Tech ben/gereeds RG | H199: =VLOOKUP(F199,Blad3!$1:$1048576,3,FALSE) -> 61411000 | I199: 0.21
A200: 5 | B200: Elektrotoestellen, machines en gereedschappen | D200: Brandstof aangedreven gereedschap | E200: Operationele werking | F200: 6141100300 | G200: Onderh/herst RG | H200: =VLOOKUP(F200,Blad3!$1:$1048576,3,FALSE) -> 61410000 | I200: 0.21
A201: 5 | B201: FD | D201: Brandstof aangedreven gereedschap | E201: Operationele werking | F201: 6141100300 | G201: Onderh/herst RG | H201: =VLOOKUP(F201,Blad3!$1:$1048576,3,FALSE) -> 61410000 | I201: 0.21
A202: 5 | B202: Elektrotoestellen, machines en gereedschappen | C202: Medische apparatuur | D202: AED toestellen | E202: Investering | F202: 2301000000 | G202: Mach en gereed | H202: =VLOOKUP(F202,Blad3!$1:$1048576,3,FALSE) -> 23010000 | I202: 0.21
A203: 5 | B203: Elektrotoestellen, machines en gereedschappen | D203: 3D Printers en lasercutters | E203: Investering | F203: 2402000000 | G203: Informatica mat | H203: =VLOOKUP(F203,Blad3!$1:$1048576,3,FALSE) -> 24020000 | I203: 0.21
A204: 5 | B204: Elektrotoestellen, machines en gereedschappen | C204: ICT- materiaal | D204: Apple producten | E204: Investering | F204: 2402000000 | G204: Informatica mat | H204: =VLOOKUP(F204,Blad3!$1:$1048576,3,FALSE) -> 24020000 | I204: 0.21
A205: 5 | B205: Elektrotoestellen, machines en gereedschappen | C205: ICT- materiaal | D205: Geluidsinstallatie | E205: Investering | F205: 2302000000 | G205: Uitr en inricht | H205: =VLOOKUP(F205,Blad3!$1:$1048576,3,FALSE) -> 23020000 | I205: 0.21
A206: 5 | B206: Elektrotoestellen, machines en gereedschappen | C206: ICT- materiaal | D206: Klein ICT materiaal buitenlandse leverancier | E206: Operationele werking | F206: 6146000900 | G206: Kantoorkosten | H206: =VLOOKUP(F206,Blad3!$1:$1048576,3,FALSE) -> 61490000 | I206: 0.21
...

Sheet Blad3
A1: Externe ID GB-rek. | B1: Korte tekst | C1: Budgetpositie
A2: 2110000000 | B2: Conc oct lic kh | C2: 21100000
A3: 2231000000 | B3: VA erfp ond/werk | C3: 22310000
A4: 2300000000 | B4: Ins/ma/uitr | C4: 23000000
A5: 2301000000 | B5: Mach en gereed | C5: 23010000
A6: 2302000000 | B6: Uitr en inricht | C6: 23020000
A7: 2400000000 | B7: Meubilair | C7: 24000000
A8: 2402000000 | B8: Informatica mat | C8: 24020000
A9: 2406000000 | B9: Buitenspeeltuigen | C9: 24060000
A10: 2410000000 | B10: Fietsen | C10: 24100000
A11: 2420000000 | B11: Muziekinstrumenten | C11: 24200000
A12: 2510000000 | B12: Leas in/ma/uitr | C12: 25100000
A16: 6030000100 | B16: MaxFac:mat/uitstap | C16: 60310100
... A161: 6570009000 | B161: Andere fin kosten | C161: 65700000
